'==============Exceptions================'
# исключения - обьекты, которые прерывают работу кода, если не были обработан

'SyntaxError'
# исключение, которое выходит, когда в коде допуущенна синтаксическая ошибка

'NameError'
'print(adasd)'
#исключение, которое выходит когда мы обращаемся к несуществующей переменной
'----------------------------------------'
'IndexError'
'''
list_ = [1,2,3,4]
list_[100000]
'''

#исключение, которое выходит при обращении к несуществуещему индексу
'--------------------------------------'
'KeyError'
'''
dict_ = {'a':1, 'b':2}
print(dict_['c'])
'''
#исключение которое выходит при обращении к несуществуещему ключу
'-----------------------------------------'
'ValueError'
#когда мы передаем в функции не коректный для нее тип данных
'''
int('10d')
'''
#когда мы распаковываем итерируемый обьект на несколько переменных и кол-во переменных не совпадают с кол-во значений
'''
a, b, c = [1, 2]
'''

'TypeError'
#когда мы пытаемся использовать методы не свойственные какому-то типу данных
#когда мы пытаемся передать в функцию больше или меньше аргументов, чем принимает функция

'''
for 1 in 1:
       ...
'''

'''
5 + '5'
'''
'''
{[1,2,3]:'a'}
'''
'ZiroDivisionError'
#выходит когда делим на ноль
'''
45 / 0 | 100 // 0 | 3 % 0
'''
'AttributeError'
#выходит когда мы обращаемся к несуществующему аттрибуту или методу обьект(тип данных)

'''[1,2,3].replace(1, 5)'''
'-------------------------------------------------'
'IntentationError'
# выходит когда мы неправильно используем отступы
'''
     a = 5

'''
'''
for i in range(10):
print(i)
'''

Exception
#исключение, которое создали, чтобы его вызывать

'==========================Вызов исключений==========================='
'raise NameError'

'=================================Try except========================================'
# конструкция, которая помогает обрабатывать исключения

# try: #конструкция try использвуют ессли разработчик не уверен или знаеет что в коде есть ошибка и хочет обработать ее в except
#     num = int(input('Введите число: '))
# except ValueError: #конструкция except нужна обработки исключения в данном случае исключение ValueError
#     print('Введите число, а не символы')
# else: # срабатывает когда не вышло ошибки исключения (когда не сработал except)
#     print(f'Вы ввели число {num}')
# finally: # работает всегда
#     print('До свидания')


# try:
#     print(number)
# except (NameError, ValueError, TypeError):
#     print('Нет такой переменной')

try:
    raise ValueError
except: # отлавливаются все ошибки
    print("Отловленна любая ошибка")

try:
    raise ValueError
except Exception:  # отлавливаются все ошибки
    print("Отловленная любая ошибка")
    





























